Workbook

Sheet C-B
A1: C-B1 | D1: C-B2 | G1: C-B3 | K1: Peaks | L1: mm | M1: MPa | N1: Error%
A2: Strain | B2: Stress | C2: Strain | D2: Strain | E2: Stress | F2: Strain | G2: Strain | H2: Stress | I2: Strain | K2: C-B1 | L2: =VLOOKUP(M2,$B$4:$C$5000,2,FALSE) -> 1.94375 | M2: =MAX(B4:B5000) -> 25.458776 | N2: =ABS((M2-$M$5))/MAX(M2,$M$5) -> 0.0084295171
A3: mm | B3: MPa | C3: mm | D3: mm | E3: MPa | F3: mm | G3: mm | H3: MPa | I3: mm | K3: C-B2 | L3: =VLOOKUP(M3,$E$4:$F$5000,2,FALSE) -> 1.673625 | M3: =MAX(E4:E5000) -> 25.766776 | N3: =ABS((M3-$M$5))/MAX(M3,$M$5) -> 0.020282128
A4: 0 | B4: 0 | C4: =A4 -> 0 | D4: 0 | E4: 0 | F4: =D4 -> 0 | G4: 0 | H4: 0 | I4: =G4 -> 0 | K4: C-B3 | L4: =VLOOKUP(M4,$H$4:$I$5000,2,FALSE) -> 1.56875 | M4: =MAX(H4:H5000) -> 24.506961 | N4: =ABS((M4-$M$5))/MAX(M4,$M$5) -> 0.029203186
A5: 0 | B5: 0.0047491547 | C5: =A5 -> 0 | D5: 0.000125 | E5: 0.00320295 | F5: =D5 -> 0.000125 | G5: 0.000125 | H5: 0.0036244005 | I5: =G5 -> 0.000125 | K5: Average | L5: =AVERAGE(L2:L4) -> 1.7287083 | M5: =AVERAGE(M2:M4) -> 25.244171 | N5: =AVERAGE(N2:N4) -> 0.019304944
A6: 0.000125 | B6: 0.0091266373 | C6: =A6 -> 0.000125 | D6: 0.00025 | E6: 0.0060687571 | F6: =D6 -> 0.00025 | G6: 0.00025 | H6: 0.0077545202 | I6: =G6 -> 0.00025 | K6: DE | L6: =_xlfn.STDEV.S(M2:M4) -> 0.6567535
A7: 0.00025 | B7: 0.014990808 | C7: =A7 -> 0.00025 | D7: 0.000375 | E7: 0.0089766936 | F7: =D7 -> 0.000375 | G7: 0.0005 | H7: 0.01281181 | I7: =G7 -> 0.0005
A8: 0.00025 | B8: 0.0206485 | C8: =A8 -> 0.00025 | D8: 0.000625 | E8: 0.012053216 | F8: =D8 -> 0.000625 | G8: 0.000625 | H8: 0.017953387 | I8: =G8 -> 0.000625
A9: 0.000625 | B9: 0.026925648 | C9: =A9 -> 0.000625 | D9: 0.00075 | E9: 0.014539722 | F9: =D9 -> 0.00075 | G9: 0.00075 | H9: 0.022167805 | I9: =G9 -> 0.00075
A10: 0.001125 | B10: 0.033739662 | C10: =A10 -> 0.001125 | D10: 0.000875 | E10: 0.016984078 | F10: =D10 -> 0.000875 | G10: 0.000875 | H10: 0.02697223 | I10: =G10 -> 0.000875
A11: 0.001375 | B11: 0.041255704 | C11: =A11 -> 0.001375 | D11: 0.001 | E11: 0.019133421 | F11: =D11 -> 0.001 | G11: 0.001 | H11: 0.032113807 | I11: =G11 -> 0.001
A12: 0.0015 | B12: 0.046706916 | C12: =A12 -> 0.0015 | D12: 0.001125 | E12: 0.021451351 | F12: =D12 -> 0.001125 | G12: 0.001125 | H12: 0.03658108 | I12: =G12 -> 0.001125
A13: 0.00175 | B13: 0.04980418 | C13: =A13 -> 0.00175 | D13: 0.001375 | E13: 0.023432127 | F13: =D13 -> 0.001375 | G13: 0.001375 | H13: 0.041385514 | I13: =G13 -> 0.001375
A14: 0.001875 | B14: 0.052364598 | C14: =A14 -> 0.001875 | D14: 0.0015 | E14: 0.026213636 | F14: =D14 -> 0.0015 | G14: 0.0015 | H14: 0.046653519 | I14: =G14 -> 0.0015
A15: 0.002125 | B15: 0.055131496 | C15: =A15 -> 0.002125 | D15: 0.001625 | E15: 0.02924801 | F15: =D15 -> 0.001625 | G15: 0.001625 | H15: 0.051289368 | I15: =G15 -> 0.001625
A16: 0.002375 | B16: 0.057980994 | C16: =A16 -> 0.002375 | D16: 0.001875 | E16: 0.032029519 | F16: =D16 -> 0.001875 | G16: 0.00175 | H16: 0.056515243 | I16: =G16 -> 0.00175
A17: 0.0025 | B17: 0.060995666 | C17: =A17 -> 0.0025 | D17: 0.002 | E17: 0.034473886 | F17: =D17 -> 0.002 | G17: 0.002 | H17: 0.062120401 | I17: =G17 -> 0.002
A18: 0.00275 | B18: 0.063390901 | C18: =A18 -> 0.00275 | D18: 0.002125 | E18: 0.037592547 | F18: =D18 -> 0.002125 | G18: 0.002125 | H18: 0.067009124 | I18: =G18 -> 0.002125
... A1386: 5.02825 | B1386: 0.62982065 | C1386: =A1386 -> 5.02825 | D1386: 6.262875 | E1386: 0.51887816 | F1386: =D1386 -> 6.262875 | G1386: 2.804125 | H1386: 3.6342543 | I1386: =G1386 -> 2.804125
A1387: 5.0415 | B1387: 0.62321313 | C1387: =A1387 -> 5.0415 | D1387: 6.28725 | E1387: 0.51310449 | F1387: =D1387 -> 6.28725 | I1387: =G1387 -> 0
A1388: 5.055 | B1388: 0.6163165 | C1388: =A1388 -> 5.055 | D1388: 6.31175 | E1388: 0.50910073 | F1388: =D1388 -> 6.31175 | I1388: =G1388 -> 0
A1389: 5.068625 | B1389: 0.60871792 | C1389: =A1389 -> 5.068625 | D1389: 6.3365 | E1389: 0.50796287 | F1389: =D1389 -> 6.3365 | I1389: =G1389 -> 0
A1390: 5.082375 | B1390: 0.60516634 | C1390: =A1390 -> 5.082375 | D1390: 6.361125 | E1390: 0.50994361 | F1390: =D1390 -> 6.361125 | I1390: =G1390 -> 0
A1391: 5.095875 | B1391: 0.60012808 | C1391: =A1391 -> 5.095875 | D1391: 6.385875 | E1391: 0.51428443 | F1391: =D1391 -> 6.385875 | I1391: =G1391 -> 0
A1392: 5.10925 | B1392: 0.59475943 | C1392: =A1392 -> 5.10925 | D1392: 6.4105 | E1392: 0.52001612 | F1392: =D1392 -> 6.4105 | I1392: =G1392 -> 0
A1393: 5.122625 | B1393: 0.58794537 | C1393: =A1393 -> 5.122625 | D1393: 6.434625 | E1393: 0.52494691 | F1393: =D1393 -> 6.434625 | I1393: =G1393 -> 0
A1394: 5.135875 | B1394: 0.57848843 | C1394: =A1394 -> 5.135875 | D1394: 6.459125 | E1394: 0.5324486 | F1394: =D1394 -> 6.459125 | I1394: =G1394 -> 0
A1395: 5.149 | B1395: 0.56766865 | C1395: =A1395 -> 5.149 | D1395: 6.483375 | E1395: 0.5417203 | F1395: =D1395 -> 6.483375 | I1395: =G1395 -> 0
A1396: 5.162 | B1396: 0.55602286 | C1396: =A1396 -> 5.162 | D1396: 6.507875 | E1396: 0.54913766 | F1396: =D1396 -> 6.507875 | I1396: =G1396 -> 0
A1397: 5.175 | B1397: 0.54640068 | C1397: =A1397 -> 5.175 | D1397: 6.5325 | E1397: 0.55259352 | F1397: =D1397 -> 6.5325 | I1397: =G1397 -> 0
A1398: 5.188 | B1398: 0.53690235 | C1398: =A1398 -> 5.188 | D1398: 6.557 | E1398: 0.5557543 | F1398: =D1398 -> 6.557 | I1398: =G1398 -> 0
... A1470: 6.116251 | B1470: 0.20491577 | C1470: =A1470 -> 6.116251 | D1470: 8.37925 | E1470: 0.69069969 | F1470: =D1470 -> 8.37925 | I1470: =G1470 -> 0
D1471: 8.404375 | E1471: 0.68269236 | F1471: =D1471 -> 8.404375 | I1471: =G1471 -> 0
D1472: 8.42875 | E1472: 0.67611789 | F1472: =D1472 -> 8.42875 | I1472: =G1472 -> 0
D1473: 8.453251 | E1473: 0.66486534 | F1473: =D1473 -> 8.453251 | I1473: =G1473 -> 0
D1474: 8.477876 | E1474: 0.64914568 | F1474: =D1474 -> 8.477876 | I1474: =G1474 -> 0
D1475: 8.50275 | E1475: 0.64438337 | F1475: =D1475 -> 8.50275 | I1475: =G1475 -> 0
D1476: 8.527375 | E1476: 0.64695409 | F1476: =D1476 -> 8.527375 | I1476: =G1476 -> 0
D1477: 8.551875 | E1477: 0.6507471 | F1477: =D1477 -> 8.551875 | I1477: =G1477 -> 0
D1478: 8.576501 | E1478: 0.65104209 | F1478: =D1478 -> 8.576501 | I1478: =G1478 -> 0
...

Sheet C-R-B
A1: C-R-B1 | D1: C-R-B2 | G1: C-R-B3 | K1: Peaks | L1: mm | M1: MPa | N1: Error%
A2: Strain | B2: Stress | C2: Strain | D2: Strain | E2: Stress | F2: Strain | G2: Strain | H2: Stress | I2: Strain | K2: C-R-B1 | L2: =VLOOKUP(M2,$B$4:$C$5000,2,FALSE) -> 1.60675 | M2: =MAX(B4:B5000) -> 25.601907 | N2: =ABS((M2-$M$5))/MAX(M2,$M$5) -> 0.006527878
A3: mm | B3: MPa | C3: mm | D3: mm | E3: MPa | F3: mm | G3: mm | H3: MPa | I3: mm | K3: C-R-B2 | L3: =VLOOKUP(M3,$E$4:$F$5000,2,FALSE) -> 1.205625 | M3: =MAX(E4:E5000) -> 25.764777 | N3: =ABS((M3-$M$5))/MAX(M3,$M$5) -> 0.00020779791
A4: 0 | B4: 0 | C4: =A4 -> 0 | D4: 0 | E4: 0 | F4: =D4 -> 0 | G4: 0 | H4: 0 | I4: =G4 -> 0 | K4: C-R-B3 | L4: =VLOOKUP(M4,$H$4:$I$5000,2,FALSE) -> 1.440375 | M4: =MAX(H4:H5000) -> 25.943711 | N4: =ABS((M4-$M$5))/MAX(M4,$M$5) -> 0.0066906101
A5: 0.0002475 | B5: 0.0046397163 | C5: =A5 -> 0.0002475 | D5: 0.000125 | E5: 0.0035625287 | F5: =D5 -> 0.000125 | G5: 0.000125 | H5: 0.0027374196 | I5: =G5 -> 0.000125 | K5: Averague | L5: =AVERAGE(L2:L4) -> 1.4175833 | M5: =AVERAGE(M2:M4) -> 25.770132 | N5: =AVERAGE(N2:N4) -> 0.0044754287
A6: 0.000375 | B6: 0.0070298731 | C6: =A6 -> 0.000375 | D6: 0.00025 | E6: 0.0071250573 | F6: =D6 -> 0.00025 | G6: 0.00025 | H6: 0.0054748393 | I6: =G6 -> 0.00025 | K6: DE | L6: =_xlfn.STDEV.S(M2:M4) -> 0.17096468
A7: 0.000625 | B7: 0.011716455 | C7: =A7 -> 0.000625 | D7: 0.000375 | E7: 0.010687586 | F7: =D7 -> 0.000375 | G7: 0.0005 | H7: 0.010949679 | I7: =G7 -> 0.0005
A8: 0.00075 | B8: 0.014059746 | C8: =A8 -> 0.00075 | D8: 0.0005 | E8: 0.014250115 | F8: =D8 -> 0.0005 | G8: 0.000625 | H8: 0.013687098 | I8: =G8 -> 0.000625
A9: 0.000875 | B9: 0.016403037 | C9: =A9 -> 0.000875 | D9: 0.00075 | E9: 0.021375172 | F9: =D9 -> 0.00075 | G9: 0.00075 | H9: 0.016424518 | I9: =G9 -> 0.00075
A10: 0.001 | B10: 0.018746328 | C10: =A10 -> 0.001 | D10: 0.000875 | E10: 0.024937701 | F10: =D10 -> 0.000875 | G10: 0.00075 | H10: 0.016424518 | I10: =G10 -> 0.00075
A11: 0.00125 | B11: 0.02343291 | C11: =A11 -> 0.00125 | D11: 0.001 | E11: 0.028500229 | F11: =D11 -> 0.001 | G11: 0.001 | H11: 0.021899357 | I11: =G11 -> 0.001
A12: 0.001375 | B12: 0.025776201 | C12: =A12 -> 0.001375 | D12: 0.001125 | E12: 0.032062758 | F12: =D12 -> 0.001125 | G12: 0.00125 | H12: 0.027374196 | I12: =G12 -> 0.00125
A13: 0.0015 | B13: 0.028119493 | C13: =A13 -> 0.0015 | D13: 0.00125 | E13: 0.035625287 | F13: =D13 -> 0.00125 | G13: 0.001375 | H13: 0.030111616 | I13: =G13 -> 0.001375
A14: 0.00175 | B14: 0.032806075 | C14: =A14 -> 0.00175 | D14: 0.0015 | E14: 0.042750344 | F14: =D14 -> 0.0015 | G14: 0.001625 | H14: 0.035586455 | I14: =G14 -> 0.001625
A15: 0.001875 | B15: 0.035149366 | C15: =A15 -> 0.001875 | D15: 0.001625 | E15: 0.046312872 | F15: =D15 -> 0.001625 | G15: 0.00175 | H15: 0.038323875 | I15: =G15 -> 0.00175
A16: 0.002 | B16: 0.037492657 | C16: =A16 -> 0.002 | D16: 0.00175 | E16: 0.049875401 | F16: =D16 -> 0.00175 | G16: 0.002 | H16: 0.043798714 | I16: =G16 -> 0.002
A17: 0.002125 | B17: 0.039835948 | C17: =A17 -> 0.002125 | D17: 0.001875 | E17: 0.05343793 | F17: =D17 -> 0.001875 | G17: 0.002125 | H17: 0.046536134 | I17: =G17 -> 0.002125
A18: 0.002375 | B18: 0.04452253 | C18: =A18 -> 0.002375 | D18: 0.002125 | E18: 0.060562987 | F18: =D18 -> 0.002125 | G18: 0.002375 | H18: 0.052010973 | I18: =G18 -> 0.002375
... A1208: 2.625875 | B1208: 11.834567 | C1208: =A1208 -> 2.625875 | D1208: 2.665375 | E1208: 9.3295318 | F1208: =D1208 -> 2.665375 | G1208: 5.52675 | H1208: 0.001537416 | I1208: =G1208 -> 5.52675
A1209: 2.63375 | B1209: 11.794282 | C1209: =A1209 -> 2.63375 | D1209: 2.67375 | E1209: 9.2570493 | F1209: =D1209 -> 2.67375 | I1209: =G1209 -> 0
A1210: 2.64175 | B1210: 11.749985 | C1210: =A1210 -> 2.64175 | D1210: 2.682375 | E1210: 9.177503 | F1210: =D1210 -> 2.682375 | I1210: =G1210 -> 0
A1211: 2.64975 | B1211: 11.706365 | C1211: =A1211 -> 2.64975 | D1211: 2.691 | E1211: 9.1043161 | F1211: =D1211 -> 2.691 | I1211: =G1211 -> 0
A1212: 2.65775 | B1212: 11.658871 | C1212: =A1212 -> 2.65775 | D1212: 2.69975 | E1212: 9.0360881 | F1212: =D1212 -> 2.69975 | I1212: =G1212 -> 0
A1213: 2.66575 | B1213: 11.611839 | C1213: =A1213 -> 2.66575 | D1213: 2.7085 | E1213: 8.9748374 | F1213: =D1213 -> 2.7085 | I1213: =G1213 -> 0
A1214: 2.673875 | B1214: 11.567042 | C1214: =A1214 -> 2.673875 | D1214: 2.717125 | E1214: 8.9179259 | F1214: =D1214 -> 2.717125 | I1214: =G1214 -> 0
A1215: 2.68175 | B1215: 11.52148 | C1215: =A1215 -> 2.68175 | D1215: 2.72575 | E1215: 8.8608874 | F1215: =D1215 -> 2.72575 | I1215: =G1215 -> 0
A1216: 2.689625 | B1216: 11.472888 | C1216: =A1216 -> 2.689625 | D1216: 2.7345 | E1216: 8.7987699 | F1216: =D1216 -> 2.7345 | I1216: =G1216 -> 0
A1217: 2.6975 | B1217: 11.42358 | C1217: =A1217 -> 2.6975 | D1217: 2.743 | E1217: 8.7357864 | F1217: =D1217 -> 2.743 | I1217: =G1217 -> 0
A1218: 2.7055 | B1218: 11.375616 | C1218: =A1218 -> 2.7055 | D1218: 2.7515 | E1218: 8.6775101 | F1218: =D1218 -> 2.7515 | I1218: =G1218 -> 0
A1219: 2.7135 | B1219: 11.329388 | C1219: =A1219 -> 2.7135 | D1219: 2.760375 | E1219: 8.6189456 | F1219: =D1219 -> 2.760375 | I1219: =G1219 -> 0
A1220: 2.72125 | B1220: 11.282904 | C1220: =A1220 -> 2.72125 | D1220: 2.769125 | E1220: 8.554804 | F1220: =D1220 -> 2.769125 | I1220: =G1220 -> 0
... A1225: 2.760375 | B1225: 11.028186 | C1225: =A1225 -> 2.760375 | D1225: 2.798625 | E1225: 8.2792013 | F1225: =D1225 -> 2.798625 | I1225: =G1225 -> 0
A1226: 2.768125 | B1226: 10.979251 | C1226: =A1226 -> 2.768125 | F1226: =D1226 -> 0 | I1226: =G1226 -> 0
A1227: 2.775875 | B1227: 10.929816 | C1227: =A1227 -> 2.775875 | F1227: =D1227 -> 0 | I1227: =G1227 -> 0
A1228: 2.78375 | B1228: 10.88241 | C1228: =A1228 -> 2.78375 | F1228: =D1228 -> 0 | I1228: =G1228 -> 0
A1229: 2.7915 | B1229: 10.83626 | C1229: =A1229 -> 2.7915 | F1229: =D1229 -> 0 | I1229: =G1229 -> 0
A1230: 2.799125 | B1230: 10.789188 | C1230: =A1230 -> 2.799125 | F1230: =D1230 -> 0 | I1230: =G1230 -> 0
A1231: 2.806875 | B1231: 10.73992 | C1231: =A1231 -> 2.806875 | F1231: =D1231 -> 0 | I1231: =G1231 -> 0
A1232: 2.8145 | B1232: 10.687493 | C1232: =A1232 -> 2.8145 | F1232: =D1232 -> 0 | I1232: =G1232 -> 0
A1233: 2.822 | B1233: 10.635018 | C1233: =A1233 -> 2.822 | F1233: =D1233 -> 0 | I1233: =G1233 -> 0
...

Sheet CRF-B
A1: CRF-B1 | D1: CRF-B2 | G1: CRF-B3 | K1: Peaks | L1: mm | M1: MPa | N1: Error%
A2: Strain | B2: Stress | C2: Strain | D2: Strain | E2: Stress | F2: Strain | G2: Strain | H2: Stress | I2: Strain | K2: CRF-B1 | L2: =VLOOKUP(M2,$B$4:$C$5000,2,FALSE) -> 1.210125 | M2: =MAX(B4:B5000) -> 28.689335 | N2: =ABS((M2-$M$5))/MAX(M2,$M$5) -> 0.009096883
A3: mm | B3: MPa | C3: mm | D3: mm | E3: MPa | F3: mm | G3: mm | H3: MPa | I3: mm | K3: CRF-B2 | L3: =VLOOKUP(M3,$E$4:$F$5000,2,FALSE) -> 1.632 | M3: =MAX(E4:E5000) -> 28.343173 | N3: =ABS((M3-$M$5))/MAX(M3,$M$5) -> 0.0029962382
A4: 0 | B4: 0 | C4: =A4 -> 0 | D4: 0 | E4: 0 | F4: =D4 -> 0 | G4: 0 | H4: 0 | I4: =G4 -> 0 | K4: CRF-B3 | L4: =VLOOKUP(M4,$H$4:$I$5000,2,FALSE) -> 1.37325 | M4: =MAX(H4:H5000) -> 28.252546 | N4: =ABS((M4-$M$5))/MAX(M4,$M$5) -> 0.0061841578
A5: 0.000125 | B5: 0.0030985174 | C5: =A5 -> 0.000125 | D5: 0.00025 | E5: 0.0049169188 | F5: =D5 -> 0.00025 | G5: 0.000125 | H5: 0.0030176773 | I5: =G5 -> 0.000125 | K5: Average | L5: =AVERAGE(L2:L4) -> 1.405125 | M5: =AVERAGE(M2:M4) -> 28.428351 | N5: =AVERAGE(N2:N4) -> 0.0060924263
A6: 0.000375 | B6: 0.0092955523 | C6: =A6 -> 0.000375 | D6: 0.000375 | E6: 0.0073753783 | F6: =D6 -> 0.000375 | G6: 0.000375 | H6: 0.0090530319 | I6: =G6 -> 0.000375 | K6: DE | L6: =_xlfn.STDEV.S(M2:M4) -> 0.230516
A7: 0.0005 | B7: 0.01239407 | C7: =A7 -> 0.0005 | D7: 0.000625 | E7: 0.012292297 | F7: =D7 -> 0.000625 | G7: 0.0005 | H7: 0.012070709 | I7: =G7 -> 0.0005
A8: 0.00075 | B8: 0.018591105 | C8: =A8 -> 0.00075 | D8: 0.00075 | E8: 0.014750757 | F8: =D8 -> 0.00075 | G8: 0.000625 | H8: 0.015088386 | I8: =G8 -> 0.000625
A9: 0.000875 | B9: 0.021689622 | C9: =A9 -> 0.000875 | D9: 0.000875 | E9: 0.017209216 | F9: =D9 -> 0.000875 | G9: 0.00075 | H9: 0.018106064 | I9: =G9 -> 0.00075
A10: 0.001 | B10: 0.024788139 | C10: =A10 -> 0.001 | D10: 0.001125 | E10: 0.022126135 | F10: =D10 -> 0.001125 | G10: 0.000875 | H10: 0.021123741 | I10: =G10 -> 0.000875
A11: 0.001125 | B11: 0.027886657 | C11: =A11 -> 0.001125 | D11: 0.00125 | E11: 0.024584594 | F11: =D11 -> 0.00125 | G11: 0.001125 | H11: 0.027159096 | I11: =G11 -> 0.001125
A12: 0.001375 | B12: 0.034083692 | C12: =A12 -> 0.001375 | D12: 0.0015 | E12: 0.029501513 | F12: =D12 -> 0.0015 | G12: 0.00125 | H12: 0.030176773 | I12: =G12 -> 0.00125
A13: 0.0015 | B13: 0.037182209 | C13: =A13 -> 0.0015 | D13: 0.001625 | E13: 0.031959972 | F13: =D13 -> 0.001625 | G13: 0.001375 | H13: 0.03319445 | I13: =G13 -> 0.001375
A14: 0.001625 | B14: 0.040280727 | C14: =A14 -> 0.001625 | D14: 0.001875 | E14: 0.036876891 | F14: =D14 -> 0.001875 | G14: 0.0015 | H14: 0.036212127 | I14: =G14 -> 0.0015
A15: 0.001875 | B15: 0.046477761 | C15: =A15 -> 0.001875 | D15: 0.002125 | E15: 0.04179381 | F15: =D15 -> 0.002125 | G15: 0.00175 | H15: 0.042247482 | I15: =G15 -> 0.00175
A16: 0.002 | B16: 0.049576279 | C16: =A16 -> 0.002 | D16: 0.00225 | E16: 0.04425227 | F16: =D16 -> 0.00225 | G16: 0.001875 | H16: 0.045265159 | I16: =G16 -> 0.001875
A17: 0.002125 | B17: 0.052674796 | C17: =A17 -> 0.002125 | D17: 0.002375 | E17: 0.046710729 | F17: =D17 -> 0.002375 | G17: 0.002 | H17: 0.048282837 | I17: =G17 -> 0.002
A18: 0.00225 | B18: 0.055773314 | C18: =A18 -> 0.00225 | D18: 0.002625 | E18: 0.051627648 | F18: =D18 -> 0.002625 | G18: 0.00225 | H18: 0.054318191 | I18: =G18 -> 0.00225
... A1052: 2.42875 | B1052: 14.145133 | C1052: =A1052 -> 2.42875 | D1052: 1.67825 | E1052: 28.203674 | F1052: =D1052 -> 1.67825 | G1052: 1.258875 | H1052: 27.244863 | I1052: =G1052 -> 1.258875
C1053: =A1053 -> 0 | D1053: 1.687875 | E1053: 28.125162 | F1053: =D1053 -> 1.687875 | G1053: 1.26075 | H1053: 27.268927 | I1053: =G1053 -> 1.26075
C1054: =A1054 -> 0 | D1054: 1.6975 | E1054: 28.038726 | F1054: =D1054 -> 1.6975 | G1054: 1.262875 | H1054: 27.295544 | I1054: =G1054 -> 1.262875
C1055: =A1055 -> 0 | D1055: 1.707125 | E1055: 27.952074 | F1055: =D1055 -> 1.707125 | G1055: 1.26475 | H1055: 27.315974 | I1055: =G1055 -> 1.26475
C1056: =A1056 -> 0 | D1056: 1.71675 | E1056: 27.866394 | F1056: =D1056 -> 1.71675 | G1056: 1.26675 | H1056: 27.345629 | I1056: =G1056 -> 1.26675
C1057: =A1057 -> 0 | D1057: 1.726625 | E1057: 27.782576 | F1057: =D1057 -> 1.726625 | G1057: 1.26875 | H1057: 27.370568 | I1057: =G1057 -> 1.26875
C1058: =A1058 -> 0 | D1058: 1.736625 | E1058: 27.699122 | F1058: =D1058 -> 1.736625 | G1058: 1.27075 | H1058: 27.396373 | I1058: =G1058 -> 1.27075
C1059: =A1059 -> 0 | D1059: 1.7465 | E1059: 27.612313 | F1059: =D1059 -> 1.7465 | G1059: 1.272625 | H1059: 27.420519 | I1059: =G1059 -> 1.272625
C1060: =A1060 -> 0 | D1060: 1.756625 | E1060: 27.52119 | F1060: =D1060 -> 1.756625 | G1060: 1.27475 | H1060: 27.447796 | I1060: =G1060 -> 1.27475
C1061: =A1061 -> 0 | D1061: 1.766875 | E1061: 27.422996 | F1061: =D1061 -> 1.766875 | G1061: 1.276625 | H1061: 27.474939 | I1061: =G1061 -> 1.276625
C1062: =A1062 -> 0 | D1062: 1.777375 | E1062: 27.312661 | F1062: =D1062 -> 1.777375 | G1062: 1.278875 | H1062: 27.501958 | I1062: =G1062 -> 1.278875
C1063: =A1063 -> 0 | D1063: 1.787875 | E1063: 27.188293 | F1063: =D1063 -> 1.787875 | G1063: 1.28075 | H1063: 27.523592 | I1063: =G1063 -> 1.28075
C1064: =A1064 -> 0 | D1064: 1.79875 | E1064: 27.050147 | F1064: =D1064 -> 1.79875 | G1064: 1.283125 | H1064: 27.55091 | I1064: =G1064 -> 1.283125
... C1155: =A1155 -> 0 | D1155: 2.872375 | E1155: 16.737278 | F1155: =D1155 -> 2.872375 | G1155: 1.6 | H1155: 24.640159 | I1155: =G1155 -> 1.6
C1156: =A1156 -> 0 | F1156: =D1156 -> 0 | G1156: 1.603875 | H1156: 24.5785 | I1156: =G1156 -> 1.603875
C1157: =A1157 -> 0 | F1157: =D1157 -> 0 | G1157: 1.60775 | H1157: 24.517182 | I1157: =G1157 -> 1.60775
C1158: =A1158 -> 0 | F1158: =D1158 -> 0 | G1158: 1.611625 | H1158: 24.45505 | I1158: =G1158 -> 1.611625
C1159: =A1159 -> 0 | F1159: =D1159 -> 0 | G1159: 1.615375 | H1159: 24.393165 | I1159: =G1159 -> 1.615375
C1160: =A1160 -> 0 | F1160: =D1160 -> 0 | G1160: 1.61925 | H1160: 24.333978 | I1160: =G1160 -> 1.61925
C1161: =A1161 -> 0 | F1161: =D1161 -> 0 | G1161: 1.623 | H1161: 24.277612 | I1161: =G1161 -> 1.623
C1162: =A1162 -> 0 | F1162: =D1162 -> 0 | G1162: 1.626875 | H1162: 24.221978 | I1162: =G1162 -> 1.626875
C1163: =A1163 -> 0 | F1163: =D1163 -> 0 | G1163: 1.63075 | H1163: 24.167908 | I1163: =G1163 -> 1.63075
...

Sheet CRF-R-B
A1: CRF-R-B1 | D1: CRF-R-B2 | G1: CRF-R-B3 | K1: Peaks | L1: mm | M1: MPa | N1: Error%
A2: Strain | B2: Stress | C2: Strain | D2: Strain | E2: Stress | F2: Strain | G2: Strain | H2: Stress | I2: Strain | K2: CRF-B1 | L2: =VLOOKUP(M2,$B$4:$C$5000,2,FALSE) -> 1.734375 | M2: =MAX(B4:B5000) -> 29.124168 | N2: =ABS((M2-$M$5))/MAX(M2,$M$5) -> 0.0075365469
A3: mm | B3: MPa | C3: mm | D3: mm | E3: MPa | F3: mm | G3: mm | H3: MPa | I3: mm | K3: CRF-B2 | L3: =VLOOKUP(M3,$E$4:$F$5000,2,FALSE) -> 1.246 | M3: =MAX(E4:E5000) -> 29.042637 | N3: =ABS((M3-$M$5))/MAX(M3,$M$5) -> 0.010314876
A4: 0 | B4: 0 | C4: =A4 -> 0 | D4: 0 | E4: 0 | F4: =D4 -> 0 | G4: 0 | H4: 0 | I4: =G4 -> 0 | K4: CRF-B3 | L4: =VLOOKUP(M4,$H$4:$I$5000,2,FALSE) -> 1.763 | M4: =MAX(H4:H5000) -> 29.869187 | N4: =ABS((M4-$M$5))/MAX(M4,$M$5) -> 0.017538339
A5: 0.00025 | B5: 0.0039737528 | C5: =A5 -> 0.00025 | D5: 0.000125 | E5: 0.003254802 | F5: =D5 -> 0.000125 | G5: 0.000125 | H5: 0.0024227454 | I5: =G5 -> 0.000125 | K5: Average | L5: =AVERAGE(L2:L4) -> 1.581125 | M5: =AVERAGE(M2:M4) -> 29.345331 | N5: =AVERAGE(N2:N4) -> 0.011796587
A6: 0.000375 | B6: 0.0059606292 | C6: =A6 -> 0.000375 | D6: 0.00025 | E6: 0.0065096039 | F6: =D6 -> 0.00025 | G6: 0.000375 | H6: 0.0072682363 | I6: =G6 -> 0.000375 | K6: DE | L6: =_xlfn.STDEV.S(M2:M4) -> 0.45550037
A7: 0.0005 | B7: 0.0079475055 | C7: =A7 -> 0.0005 | D7: 0.000375 | E7: 0.0097644059 | F7: =D7 -> 0.000375 | G7: 0.0005 | H7: 0.0096909818 | I7: =G7 -> 0.0005
A8: 0.000625 | B8: 0.0099343819 | C8: =A8 -> 0.000625 | D8: 0.0005 | E8: 0.013019208 | F8: =D8 -> 0.0005 | G8: 0.000625 | H8: 0.012113727 | I8: =G8 -> 0.000625
A9: 0.000875 | B9: 0.013908135 | C9: =A9 -> 0.000875 | D9: 0.000625 | E9: 0.01627401 | F9: =D9 -> 0.000625 | G9: 0.000875 | H9: 0.016959218 | I9: =G9 -> 0.000875
A10: 0.001 | B10: 0.015895011 | C10: =A10 -> 0.001 | D10: 0.00075 | E10: 0.019528812 | F10: =D10 -> 0.00075 | G10: 0.001 | H10: 0.019381964 | I10: =G10 -> 0.001
A11: 0.001125 | B11: 0.017881887 | C11: =A11 -> 0.001125 | D11: 0.001 | E11: 0.026038416 | F11: =D11 -> 0.001 | G11: 0.001125 | H11: 0.021804709 | I11: =G11 -> 0.001125
A12: 0.001125 | B12: 0.017881887 | C12: =A12 -> 0.001125 | D12: 0.001125 | E12: 0.029293218 | F12: =D12 -> 0.001125 | G12: 0.00125 | H12: 0.024227454 | I12: =G12 -> 0.00125
A13: 0.001375 | B13: 0.02185564 | C13: =A13 -> 0.001375 | D13: 0.00125 | E13: 0.03254802 | F13: =D13 -> 0.00125 | G13: 0.0015 | H13: 0.029072945 | I13: =G13 -> 0.0015
A14: 0.001625 | B14: 0.025829393 | C14: =A14 -> 0.001625 | D14: 0.001375 | E14: 0.035802822 | F14: =D14 -> 0.001375 | G14: 0.001625 | H14: 0.031495691 | I14: =G14 -> 0.001625
A15: 0.00175 | B15: 0.027816269 | C15: =A15 -> 0.00175 | D15: 0.001625 | E15: 0.042312426 | F15: =D15 -> 0.001625 | G15: 0.00175 | H15: 0.033918436 | I15: =G15 -> 0.00175
A16: 0.001875 | B16: 0.029803146 | C16: =A16 -> 0.001875 | D16: 0.00175 | E16: 0.045567227 | F16: =D16 -> 0.00175 | G16: 0.001875 | H16: 0.036341182 | I16: =G16 -> 0.001875
A17: 0.002 | B17: 0.031790022 | C17: =A17 -> 0.002 | D17: 0.001875 | E17: 0.048822029 | F17: =D17 -> 0.001875 | G17: 0.002125 | H17: 0.041186673 | I17: =G17 -> 0.002125
A18: 0.002125 | B18: 0.033776899 | C18: =A18 -> 0.002125 | D18: 0.002 | E18: 0.052076831 | F18: =D18 -> 0.002 | G18: 0.00225 | H18: 0.043609418 | I18: =G18 -> 0.00225
... A1038: 1.24225 | B1038: 22.8569 | C1038: =A1038 -> 1.24225 | D1038: 2.386625 | E1038: 15.649465 | F1038: =D1038 -> 2.386625 | G1038: 1.158625 | H1038: 22.690514 | I1038: =G1038 -> 1.158625
A1039: 1.243875 | B1039: 22.891158 | C1039: =A1039 -> 1.243875 | F1039: =D1039 -> 0 | G1039: 1.16025 | H1039: 22.718726 | I1039: =G1039 -> 1.16025
A1040: 1.24475 | B1040: 22.90616 | C1040: =A1040 -> 1.24475 | F1040: =D1040 -> 0 | G1040: 1.161375 | H1040: 22.746312 | I1040: =G1040 -> 1.161375
A1041: 1.2465 | B1041: 22.945701 | C1041: =A1041 -> 1.2465 | F1041: =D1041 -> 0 | G1041: 1.16275 | H1041: 22.771236 | I1041: =G1041 -> 1.16275
A1042: 1.24725 | B1042: 22.95607 | C1042: =A1042 -> 1.24725 | F1042: =D1042 -> 0 | G1042: 1.164 | H1042: 22.796531 | I1042: =G1042 -> 1.164
A1043: 1.24925 | B1043: 22.9977 | C1043: =A1043 -> 1.24925 | F1043: =D1043 -> 0 | G1043: 1.165375 | H1043: 22.823152 | I1043: =G1043 -> 1.165375
A1044: 1.249875 | B1044: 23.008193 | C1044: =A1044 -> 1.249875 | F1044: =D1044 -> 0 | G1044: 1.166625 | H1044: 22.855372 | I1044: =G1044 -> 1.166625
A1045: 1.251875 | B1045: 23.049474 | C1045: =A1045 -> 1.251875 | F1045: =D1045 -> 0 | G1045: 1.167875 | H1045: 22.877072 | I1045: =G1045 -> 1.167875
A1046: 1.252375 | B1046: 23.057752 | C1046: =A1046 -> 1.252375 | F1046: =D1046 -> 0 | G1046: 1.16925 | H1046: 22.908296 | I1046: =G1046 -> 1.16925
A1047: 1.254375 | B1047: 23.101195 | C1047: =A1047 -> 1.254375 | F1047: =D1047 -> 0 | G1047: 1.1705 | H1047: 22.928076 | I1047: =G1047 -> 1.1705
A1048: 1.255 | B1048: 23.108795 | C1048: =A1048 -> 1.255 | F1048: =D1048 -> 0 | G1048: 1.172 | H1048: 22.958748 | I1048: =G1048 -> 1.172
A1049: 1.257125 | B1049: 23.154153 | C1049: =A1049 -> 1.257125 | F1049: =D1049 -> 0 | G1049: 1.173 | H1049: 22.978528 | I1049: =G1049 -> 1.173
A1050: 1.257625 | B1050: 23.161041 | C1050: =A1050 -> 1.257625 | F1050: =D1050 -> 0 | G1050: 1.174625 | H1050: 23.014217 | I1050: =G1050 -> 1.174625
... A1380: 2.83775 | B1380: 14.979831 | C1380: =A1380 -> 2.83775 | F1380: =D1380 -> 0 | G1380: 3.163625 | H1380: 13.418324 | I1380: =G1380 -> 3.163625
A1381: 2.849875 | B1381: 14.896704 | C1381: =A1381 -> 2.849875 | F1381: =D1381 -> 0 | I1381: =G1381 -> 0
A1382: 2.861875 | B1382: 14.814791 | C1382: =A1382 -> 2.861875 | F1382: =D1382 -> 0 | I1382: =G1382 -> 0
A1383: 2.873875 | B1383: 14.732405 | C1383: =A1383 -> 2.873875 | F1383: =D1383 -> 0 | I1383: =G1383 -> 0
A1384: 2.886625 | B1384: 14.649628 | C1384: =A1384 -> 2.886625 | F1384: =D1384 -> 0 | I1384: =G1384 -> 0
A1385: 2.89875 | B1385: 14.569929 | C1385: =A1385 -> 2.89875 | F1385: =D1385 -> 0 | I1385: =G1385 -> 0
A1386: 2.9105 | B1386: 14.496213 | C1386: =A1386 -> 2.9105 | F1386: =D1386 -> 0 | I1386: =G1386 -> 0
A1387: 2.9225 | B1387: 14.424752 | C1387: =A1387 -> 2.9225 | F1387: =D1387 -> 0 | I1387: =G1387 -> 0
A1388: 2.93425 | B1388: 14.352817 | C1388: =A1388 -> 2.93425 | F1388: =D1388 -> 0 | I1388: =G1388 -> 0
...

Sheet Elastic Modulus (Without Bars)
A1: Concrete Normal
A2: Concrete with Fibers
B4: f´c (MPa) | C4: f´c (Δmm) | D4: 5%f´c (MPa) | E4: 45%f´c (MPa) | F4: 5%f´c (Δmm) | G4: 45%f´c (Δmm) | H4: E (MPa) | I4: Ec (MPa) | J4: Em (MPa)
A5: C1 | B5: ='C-B'!M2 -> 25.458776 | C5: ='C-B'!L2 -> 1.94375 | D5: =5%*B5 -> 1.2729388 | E5: =45%*B5 -> 11.456449 | F5: =VLOOKUP(D5,'C-B'!B4:C1571,2,TRUE) -> 0.075625 | G5: =VLOOKUP(E5,'C-B'!B4:C1571,2,TRUE) -> 0.6948751 | H5: =(E5-D5)/((G5-F5)/200) -> 3288.9814 | I5: =E5/(G5/200) -> 3297.4125 | J5: =B5/(C5/200) -> 2619.5525
A6: C2 | B6: ='C-B'!M3 -> 25.766776 | C6: ='C-B'!L3 -> 1.673625 | D6: =5%*B6 -> 1.2883388 | E6: =45%*B6 -> 11.595049 | F6: =VLOOKUP(D6,'C-B'!E4:F1588,2,TRUE) -> 0.05925 | G6: =VLOOKUP(E6,'C-B'!E4:F1588,2,TRUE) -> 0.617125 | H6: =(E6-D6)/((G6-F6)/200) -> 3694.9891 | I6: =E6/(G6/200) -> 3757.7635 | J6: =B6/(C6/200) -> 3079.1576
A7: C3 | B7: ='C-B'!M4 -> 24.506961 | C7: ='C-B'!L4 -> 1.56875 | D7: =5%*B7 -> 1.225348 | E7: =45%*B7 -> 11.028132 | F7: =VLOOKUP(D7,'C-B'!H4:I1559,2,TRUE) -> 0.053 | G7: =VLOOKUP(E7,'C-B'!H4:I1559,2,TRUE) -> 0.7097501 | H7: =(E7-D7)/((G7-F7)/200) -> 2985.2403 | I7: =E7/(G7/200) -> 3107.6099 | J7: =B7/(C7/200) -> 3124.3934
A8: Average | B8: =AVERAGE(B5:B7) -> 25.244171 | C8: =AVERAGE(C5:C7) -> 1.7287083 | D8: =AVERAGE(D5:D7) -> 1.2622085 | E8: =AVERAGE(E5:E7) -> 11.359877 | F8: =AVERAGE(F5:F7) -> 0.062625 | G8: =AVERAGE(G5:G7) -> 0.67391673 | H8: =AVERAGE(H5:H7) -> 3323.0703 | I8: =AVERAGE(I5:I7) -> 3387.5953 | J8: =AVERAGE(J5:J7) -> 2941.0345
B10: f´c (MPa) | C10: f´c (Δmm) | D10: 5%f´c (MPa) | E10: 45%f´c (MPa) | F10: 5%f´c (Δmm) | G10: 45%f´c (Δmm) | H10: E (MPa) | I10: Ec (MPa) | J10: Em (MPa)
A11: C1 | B11: ='CRF-B'!M2 -> 28.689335 | C11: ='CRF-B'!L2 -> 1.210125 | D11: =5%*B11 -> 1.4344667 | E11: =45%*B11 -> 12.910201 | F11: =VLOOKUP(D11,'CRF-B'!B4:C1173,2,TRUE) -> 0.057625 | G11: =VLOOKUP(E11,'CRF-B'!B4:C1173,2,TRUE) -> 0.5181251 | H11: =(E11-D11)/((G11-F11)/200) -> 4984.0311 | I11: =E11/(G11/200) -> 4983.43 | J11: =B11/(C11/200) -> 4741.549
A12: C2 | B12: ='CRF-B'!M3 -> 28.343173 | C12: ='CRF-B'!L3 -> 1.632 | D12: =5%*B12 -> 1.4171587 | E12: =45%*B12 -> 12.754428 | F12: =VLOOKUP(D12,'CRF-B'!E4:F1360,2,TRUE) -> 0.071 | G12: =VLOOKUP(E12,'CRF-B'!E4:F1360,2,TRUE) -> 0.649125 | H12: =(E12-D12)/((G12-F12)/200) -> 3922.0824 | I12: =E12/(G12/200) -> 3929.7294 | J12: =B12/(C12/200) -> 3473.4281
A13: C3 | B13: ='CRF-B'!M4 -> 28.252546 | C13: ='CRF-B'!L4 -> 1.37325 | D13: =5%*B13 -> 1.4126273 | E13: =45%*B13 -> 12.713646 | F13: =VLOOKUP(D13,'CRF-B'!H4:I1480,2,TRUE) -> 0.057375 | G13: =VLOOKUP(E13,'CRF-B'!H4:I1480,2,TRUE) -> 0.568 | H13: =(E13-D13)/((G13-F13)/200) -> 4426.3475 | I13: =E13/(G13/200) -> 4476.6358 | J13: =B13/(C13/200) -> 4114.6981
A14: Average | B14: =AVERAGE(B11:B13) -> 28.428351 | C14: =AVERAGE(C11:C13) -> 1.405125 | D14: =AVERAGE(D11:D13) -> 1.4214176 | E14: =AVERAGE(E11:E13) -> 12.792758 | F14: =AVERAGE(F11:F13) -> 0.062 | G14: =AVERAGE(G11:G13) -> 0.5784167 | H14: =AVERAGE(H11:H13) -> 4444.1536 | I14: =AVERAGE(I11:I13) -> 4463.2651 | J14: =AVERAGE(J11:J13) -> 4109.8917
